метод exceptionDemo() в блоке try выбросил исключение типа ArithmeticException, а блок catch, обрабатывающий любое исключение(за счет принимаемого аргумента типа Exception), обработал его и вывел "Infinity"